Workbook

Sheet README
A1: Praxion HROS — Phase-1 Jira Backlog v1.0
A2: Project key: PRX · 22 × 2-week sprints · 2026-05-01 → 2027-03-18 · Team: 2 FE + 2 BE + 1 QA + TL + PO + Designer
A5: HOW TO IMPORT INTO JIRA CLOUD
A6: 1. Create Jira project | B6: In Jira Cloud → Create project → Scrum template → Name: Praxion HROS → Key: PRX
A7: 2. Configure components | B7: Settings → Components → add: M1-Core-HRIS, M10-Sys-Admin, Platform, Integrations, Design, DevOps
A8: 3. Configure labels & priorities | B8: Priorities already in Jira (P0-P4). Labels are free-text so they auto-create on import.
A9: 4. Import Epics first | B9: System → External System Import → CSV. Upload Epics sheet (save as CSV). Map: Issue Type, Summary, Description, Priority, Components, Labels.
A10: 5. Import Stories | B10: Same CSV import. Map: Issue Type, Summary, Description, Priority, Assignee, Epic Link, Sprint, Components, Labels, Story Points.
A11: 6. Import Sub-tasks | B11: Same CSV import. Map: Issue Type, Summary, Parent, Assignee, Original Estimate.
A12: 7. Create sprints in Jira | B12: Backlog view → Create Sprint → name + dates per Sprints sheet. Bulk-move stories into sprints by the Sprint field.
A13: 8. Set up Board filters | B13: Board → Configure → quick-filters: FE (label=fe), BE (label=be), QA (label=qa), Design (label=design), Bugs (type=Bug).
A15: SHEETS IN THIS WORKBOOK
A16: Sprints | B16: 22 sprints + Sprint 0 with dates, phase gate, goal, target SP budget.
A17: Team | B17: 8-seat roster with role, discipline, capacity per sprint, Jira labels.
A18: Epics | B18: 9 epics ready for Jira CSV import. Covers P0-P7 + Bug Tracker.
A19: Stories | B19: 219 stories across all phase gates. Jira CSV format with Epic Link + Sprint + SP.
A20: Sub-tasks | B20: 575 sub-tasks (representative patterns for stories ≥3 SP). Each has Parent link to its story.
A21: Workload | B21: SP per assignee per sprint. Formulas. Flags over-allocation.
A22: Bug-Log | B22: Empty Jira-CSV-ready bug template. Log defects as they arise, then bulk-import to Jira project PRX.
A23: Capacity-Check | B23: Sprint-by-sprint utilisation %. Target: ≤95%. Formulas.
A25: FIELD MAPPING CHEAT-SHEET
A26: Summary | B26: Jira ‘Summary’ field. Keep ≤ 240 chars for readability.
A27: Description | B27: Jira ‘Description’ (wiki markup). Long-form context.
A28: Priority | B28: P0 Blocker · P1 Critical · P2 Major · P3 Minor · P4 Trivial.
A29: Assignee (role) | B29: Role placeholder: DEV-FE-1, DEV-BE-1, QA-1, TL, PO, DES-1. Replace with real user IDs after hiring.
A30: Epic Link | B30: PRX-E0 … PRX-E8. Must match Epic key in the Epics sheet.
A31: Sprint | B31: Sprint name from Sprints sheet (e.g., ‘Sprint 6 — P3 Core Build · Employee records CRUD’).
A32: Components | B32: One of: M1-Core-HRIS, M10-Sys-Admin, Platform, Integrations, Design, DevOps.
A33: Labels | B33: Comma-sep: fe/be/qa/devops/design/po/tl + foundation/platform/bug/security/a11y/uat/training/migration/cutover/go-live.
A34: Story Points | B34: Fibonacci: 1, 2, 3, 5, 8. Stories ≥8 SP should be split before sprint start.
A35: Original Estimate (subtasks) | B35: Hours. Rough guide for daily stand-up planning.
A37: WHY THIS SHAPE
A38: Discipline split (FE/BE/QA/DES/PO/TL) | B38: Every feature surfaces at least one BE + one FE + one QA story so work is parallelisable across the 4 devs.
A39: Epic per phase gate | B39: P0-P7 + Bug Tracker. Lets you track burndown at gate level and maintain the rhythm set in the Executive Roadmap v2.0.
A40: Ramp-up sprints (S1-S3 lower SP) | B40: S0 20 SP, S1 35 SP, S2 45 SP, S3 50 SP. Team hits 56 SP steady state by S4.
A41: Buffer epic (PRX-E8 Bugs) | B41: 80 SP reserved across the project for bug work discovered mid-sprint. Prevents scope creep eroding feature delivery.
A43: NEXT STEPS
A44: KNOWN CAPACITY RISK (flagged for TL refinement)
A45: Core-build sprints (S6-S10) run at 108-116% of dev capacity | B45: With 2 BE + 2 FE devs (56 SP/sprint), honest scope to deliver M1 + M10 by 14-Mar needs ~64 SP/sprint in Core Build. Options: (a) add a 5th dev (3rd BE), (b) extend by 2 sprints, or (c) accept 15-16 SP/dev during hot phase. Decision needed at Sprint 0 planning.
A47: A) Connect Atlassian Rovo MCP | B47: If you enable the Atlassian connector in Cowork, I can push this backlog directly into Jira instead of CSV-import.
...

Sheet Sprints
A1: Sprint calendar — Phase-1 (22 sprints, 2-week cadence)
A3: Sprint # | B3: Start date | C3: End date | D3: Phase gate | E3: Sprint goal | F3: Target SP | G3: Notes
A4: Sprint 0 | B4: 46143 | C4: 46156 | D4: P0 close / Kick-off | E4: Team onboarded, environments ready, CI/CD green, design system scaffold | F4: 20 | G4: Ramp sprint
A5: Sprint 1 | B5: 46157 | C5: 46170 | D5: P1 Discover | E5: Discovery M1 — employee records & org structure flow | F5: 35 | G5: Ramp sprint
A6: Sprint 2 | B6: 46171 | C6: 46184 | D6: P1 Discover | E6: Discovery M1 — positions & contracts + M10 discovery | F6: 45 | G6: Ramp sprint
A7: Sprint 3 | B7: 46185 | C7: 46198 | D7: P1→P2 Design | E7: Design system complete + all M1 wireframes signed off | F7: 50 | G7: Ramp sprint
A8: Sprint 4 | B8: 46199 | C8: 46212 | D8: P2 Foundations | E8: Tenancy model + SSO + RBAC scaffold | F8: 56
A9: Sprint 5 | B9: 46213 | C9: 46226 | D9: P2 Foundations | E9: Audit log + platform shell + nav | F9: 56
A10: Sprint 6 | B10: 46227 | C10: 46240 | D10: P3 Core Build | E10: Employee records CRUD + search + data model in place | F10: 56
A11: Sprint 7 | B11: 46241 | C11: 46254 | D11: P3 Core Build | E11: Org structure + positions + assignment | F11: 56
A12: Sprint 8 | B12: 46255 | C12: 46268 | D12: P3 Core Build | E12: Contracts + documents vault + signed URLs | F12: 56
A13: Sprint 9 | B13: 46269 | C13: 46282 | D13: P3 Core Build | E13: Lifecycle events + approvals engine + notifications | F13: 56
A14: Sprint 10 | B14: 46283 | C14: 46296 | D14: P3→P4 | E14: M1 polish + bulk import/export + M10 scaffold | F14: 56
A15: Sprint 11 | B15: 46297 | C15: 46310 | D15: P4 Adjacent | E15: M10 users, roles, permissions admin | F15: 56
A16: Sprint 12 | B16: 46311 | C16: 46324 | D16: P4 Adjacent | E16: M10 tenant config + org chart admin + holiday calendar | F16: 56
A17: Sprint 13 | B17: 46325 | C17: 46338 | D17: P4 Adjacent | E17: M10 audit dashboard + integrations + webhooks + API tokens | F17: 56
A18: Sprint 14 | B18: 46339 | C18: 46352 | D18: P4→P5 | E18: Feature-freeze — a11y + bundle + perf optimizations | F18: 56
A19: Sprint 15 | B19: 46353 | C19: 46366 | D19: P5 Harden | E19: Load test + security scan fixes + DR drill | F19: 56
A20: Sprint 16 | B20: 46367 | C20: 46380 | D20: P5 Harden | E20: Pen-test fixes + data migration dry-runs | F20: 56
A21: Sprint 17 | B21: 46381 | C21: 46394 | D21: P5→P6 | E21: Holiday-reduced · UAT prep — scenarios, test data, env | F21: 35 | G21: Holiday-reduced
A22: Sprint 18 | B22: 46395 | C22: 46408 | D22: P6 UAT | E22: UAT round 1 + defect burndown | F22: 56
A23: Sprint 19 | B23: 46409 | C23: 46422 | D23: P6 UAT | E23: UAT round 2 + training content | F23: 56
A24: Sprint 20 | B24: 46423 | C24: 46436 | D24: P6 UAT | E24: UAT round 3 + cutover rehearsal | F24: 56
A25: Sprint 21 | B25: 46437 | C25: 46450 | D25: P7 Cutover | E25: Final fixes + go-live prep + rollback rehearsal | F25: 56
A26: Sprint 22 | B26: 46451 | C26: 46464 | D26: P7 Go-Live | E26: GO-LIVE 14-Mar-2027 + Day-1 hypercare | F26: 56 | G26: GO-LIVE sprint

Sheet Team
A1: Delivery team — Phase-1 (8 seats)
A3: Jira User ID (placeholder) | B3: Name | C3: Role | D3: Jira label | E3: Capacity SP / sprint | F3: Email
A4: PRX-PO | B4: Sabry M. (placeholder) | C4: Project Director / PO | D4: po | E4: — | F4: mohamed.sabry@praxionhr.com
A5: PRX-TL | B5: TL — to hire | C5: Tech Lead | D5: tl | E5: 8 | F5: tl@praxionhr.com
A6: PRX-FE1 | B6: DEV-FE-1 — to hire | C6: Frontend Engineer | D6: fe | E6: 14 | F6: fe1@praxionhr.com
A7: PRX-FE2 | B7: DEV-FE-2 — to hire | C7: Frontend Engineer | D7: fe | E7: 14 | F7: fe2@praxionhr.com
A8: PRX-BE1 | B8: DEV-BE-1 — to hire | C8: Backend Engineer | D8: be | E8: 14 | F8: be1@praxionhr.com
A9: PRX-BE2 | B9: DEV-BE-2 — to hire | C9: Backend Engineer | D9: be | E9: 14 | F9: be2@praxionhr.com
A10: PRX-QA1 | B10: QA-1 — to hire | C10: QA Engineer | D10: qa | E10: 14 | F10: qa1@praxionhr.com
A11: PRX-DES | B11: DES-1 — to hire (full-time S1-S3 · 50% from S4) | C11: Product Designer | D11: design | E11: 14→7 | F11: des1@praxionhr.com
D12: Team capacity / sprint → | E12: =SUMIF(E4:E11,">0") -> 0

Sheet Epics
A1: Epics — Jira CSV import format (9 epics)
A3: Issue Type | B3: Issue Key (for import reference) | C3: Summary | D3: Description | E3: Priority | F3: Assignee (role) | G3: Components | H3: Labels
A4: Epic | B4: PRX-E0 | C4: P0 — Mobilisation close-out | D4: Close out mobilization: environments, CI/CD, team onboarding, design-system scaffold. Sprint range: S0-0. | E4: P1 | F4: PO | G4: Platform | H4: foundation,platform
A5: Epic | B5: PRX-E1 | C5: P1 — Discover & Design | D5: Functional discovery + visual design for M1 Core HRIS and M10 Sys Admin. Ends with Design Sign-Off. Sprint range: S1-3. | E5: P1 | F5: TL | G5: M1-Core-HRIS | H5: foundation
A6: Epic | B6: PRX-E2 | C6: P2 — Platform Foundations | D6: Tenancy, SSO, RBAC, audit log, platform shell — the chassis before functional modules. Sprint range: S4-5. | E6: P1 | F6: TL | G6: Platform | H6: foundation,platform
A7: Epic | B7: PRX-E3 | C7: P3 — M1 Core HRIS Build | D7: Employee records, org structure, positions, contracts, documents, lifecycle events, approvals. Sprint range: S6-10. | E7: P1 | F7: TL | G7: M1-Core-HRIS | H7: foundation
A8: Epic | B8: PRX-E4 | C8: P4 — M10 System Admin Build | D8: M10 Sys Admin: users, roles, permissions, tenant config, audit dashboard, integrations. Sprint range: S11-14. | E8: P2 | F8: TL | G8: M10-Sys-Admin | H8: foundation
A9: Epic | B9: PRX-E5 | C9: P5 — Hardening & Security | D9: Perf, load-test, security review, pen-test fixes, DR drill, data migration rehearsal. Sprint range: S15-17. | E9: P1 | F9: TL | G9: Platform | H9: platform,qa
A10: Epic | B10: PRX-E6 | C10: P6 — UAT & Defect Burndown | D10: 3 UAT rounds with stakeholders, defect triage, training content, cutover rehearsal. Sprint range: S18-20. | E10: P1 | F10: QA-1 | G10: Platform | H10: qa
A11: Epic | B11: PRX-E7 | C11: P7 — Cutover & Go-Live | D11: Production cutover 14-Mar-2027 + Day-1 hypercare support. Sprint range: S21-22. | E11: P0 | F11: TL | G11: Platform | H11: foundation,platform
A12: Epic | B12: PRX-E8 | C12: Bug Tracker (cross-cutting) | D12: Defects raised during any sprint. Workflow: Open→Triaged→In Progress→Ready QA→Verified→Closed. Sprint range: S0-22. | E12: P1 | F12: QA-1 | G12: Platform | H12: bug

Sheet Stories
A1: Stories — Jira CSV import format (219 stories)
A3: Issue Type | B3: Summary | C3: Description | D3: Priority | E3: Assignee | F3: Epic Link | G3: Sprint | H3: Components | I3: Labels | J3: Story Points | K3: Reporter
A4: Story | B4: DEVOPS: Provision dev/stage/prod environments | C4: Kubernetes clusters + managed Postgres + S3 buckets + Redis across 3 envs. Networking + secrets vault. | D4: P1 | E4: DEV-BE-1 | F4: PRX-E0 | G4: Sprint 0 — P0 close / Kick-off · Team onboarded, environments ready, CI/C | H4: Platform | I4: devops,platform | J4: 5 | K4: PO
A5: Story | B5: DEVOPS: Set up CI/CD pipeline (BE + FE) | C5: GitHub Actions: lint → test → build → deploy. Branch protection rules. Preview envs on PR. | D5: P1 | E5: DEV-BE-2 | F5: PRX-E0 | G5: Sprint 0 — P0 close / Kick-off · Team onboarded, environments ready, CI/C | H5: Platform | I5: devops,platform | J5: 5 | K5: PO
A6: Story | B6: FE: Bootstrap FE repo + design system package | C6: Vite + React + TS + Tailwind + routing. Shared @praxion/ui package scaffold. Storybook. | D6: P1 | E6: DEV-FE-1 | F6: PRX-E0 | G6: Sprint 0 — P0 close / Kick-off · Team onboarded, environments ready, CI/C | H6: Platform | I6: fe,platform | J6: 3 | K6: PO
A7: Story | B7: FE: Design system token package (colors/type/spacing) | C7: Brand v2.0 tokens wired into @praxion/tokens. TS types + CSS vars. Tailwind plugin. | D7: P1 | E7: DEV-FE-2 | F7: PRX-E0 | G7: Sprint 0 — P0 close / Kick-off · Team onboarded, environments ready, CI/C | H7: Platform | I7: fe,platform,design | J7: 3 | K7: PO
A8: Story | B8: QA: Test framework + first smoke tests | C8: Playwright for e2e, Vitest for unit, Pact for contract. Smoke test hits staging health endpoint. | D8: P1 | E8: QA-1 | F8: PRX-E0 | G8: Sprint 0 — P0 close / Kick-off · Team onboarded, environments ready, CI/C | H8: Platform | I8: qa,platform | J8: 2 | K8: PO
A9: Story | B9: DEVOPS: Observability — logging + metrics + tracing | C9: Stack: Loki + Prometheus + Grafana + OTEL. Dashboards for p50/p95 latency + error rate. | D9: P1 | E9: DEV-BE-1 | F9: PRX-E0 | G9: Sprint 0 — P0 close / Kick-off · Team onboarded, environments ready, CI/C | H9: Platform | I9: devops,platform | J9: 2 | K9: PO
A10: Story | B10: PO: Stakeholder interviews — Records management | C10: Interview HR Ops + People team. Document: attributes, lifecycle states, data sources. | D10: P1 | E10: PO | F10: PRX-E1 | G10: Sprint 1 — P1 Discover · Discovery M1 — employee records & org st | H10: M1-Core-HRIS | I10: po,foundation | J10: 3 | K10: PO
A11: Story | B11: PO: Stakeholder interviews — Org structure | C11: Interview Finance + HR Ops. Document: cost-centre model, reporting lines, org depth. | D11: P1 | E11: PO | F11: PRX-E1 | G11: Sprint 1 — P1 Discover · Discovery M1 — employee records & org st | H11: M1-Core-HRIS | I11: po,foundation | J11: 3 | K11: PO
A12: Story | B12: TL: Spike — Auth provider comparison (Auth0/Keycloak/Cognito) | C12: POC 3 providers against SSO req. Document trade-offs + cost. Recommend provider. | D12: P1 | E12: TL | F12: PRX-E1 | G12: Sprint 1 — P1 Discover · Discovery M1 — employee records & org st | H12: Platform | I12: tl,platform | J12: 3 | K12: PO
A13: Story | B13: TL: Spike — Multi-tenancy pattern selection | C13: Evaluate: row-level-sec vs schema-per-tenant vs db-per-tenant. Benchmark + recommend. | D13: P1 | E13: TL | F13: PRX-E1 | G13: Sprint 1 — P1 Discover · Discovery M1 — employee records & org st | H13: Platform | I13: tl,platform | J13: 3 | K13: PO
A14: Story | B14: DES: UX research synthesis (existing materials) | C14: Synthesize discovery docs, Meeting-Docs-Apr22, master layout feedback. Personas + journeys. | D14: P1 | E14: DES-1 | F14: PRX-E1 | G14: Sprint 1 — P1 Discover · Discovery M1 — employee records & org st | H14: M1-Core-HRIS | I14: design,foundation | J14: 5 | K14: PO
A15: Story | B15: BE: Data model design — Employees + audit fields | C15: ERD draft: employees, addresses, emergency contacts, identifiers. Include audit/soft-delete. | D15: P1 | E15: DEV-BE-1 | F15: PRX-E1 | G15: Sprint 1 — P1 Discover · Discovery M1 — employee records & org st | H15: M1-Core-HRIS | I15: be,foundation | J15: 5 | K15: PO
... A222: Story | B222: PO: Go-live retrospective (what went well / improve) | C222: Retro with full team + stakeholders. Lessons logged + fed into Phase-2 plan. | D222: P1 | E222: PO | F222: PRX-E7 | G222: Sprint 22 — P7 Go-Live · GO-LIVE 14-Mar-2027 + Day-1 hypercare | H222: Platform | I222: po,retro | J222: 3 | K222: PO

Sheet Sub-tasks
A1: Sub-tasks — representative patterns (575 sub-tasks)
A2: Note — these are representative sub-tasks for ≥3 SP stories. Refine per story during sprint refinement in Jira.
A4: Issue Type | B4: Summary | C4: Parent Summary | D4: Assignee | E4: Original Estimate (hrs) | F4: Labels
A5: Sub-task | B5: Schema/migration — Provision dev/stage/prod environments | C5: DEVOPS: Provision dev/stage/prod environments | D5: DEV-BE-1 | E5: 4 | F5: sub
A6: Sub-task | B6: Implementation — Provision dev/stage/prod environments | C6: DEVOPS: Provision dev/stage/prod environments | D6: DEV-BE-1 | E6: 10 | F6: sub
A7: Sub-task | B7: Unit + integration tests — Provision dev/stage/prod environments | C7: DEVOPS: Provision dev/stage/prod environments | D7: DEV-BE-1 | E7: 4 | F7: sub
A8: Sub-task | B8: Schema/migration — Set up CI/CD pipeline (BE + FE) | C8: DEVOPS: Set up CI/CD pipeline (BE + FE) | D8: DEV-BE-2 | E8: 4 | F8: sub
A9: Sub-task | B9: Implementation — Set up CI/CD pipeline (BE + FE) | C9: DEVOPS: Set up CI/CD pipeline (BE + FE) | D9: DEV-BE-2 | E9: 10 | F9: sub
A10: Sub-task | B10: Unit + integration tests — Set up CI/CD pipeline (BE + FE) | C10: DEVOPS: Set up CI/CD pipeline (BE + FE) | D10: DEV-BE-2 | E10: 4 | F10: sub
A11: Sub-task | B11: Component/page build — Bootstrap FE repo + design system package | C11: FE: Bootstrap FE repo + design system package | D11: DEV-FE-1 | E11: 8 | F11: sub
A12: Sub-task | B12: State wiring + form validation — Bootstrap FE repo + design system package | C12: FE: Bootstrap FE repo + design system package | D12: DEV-FE-1 | E12: 4 | F12: sub
A13: Sub-task | B13: E2E + a11y pass — Bootstrap FE repo + design system package | C13: FE: Bootstrap FE repo + design system package | D13: DEV-FE-1 | E13: 3 | F13: sub
A14: Sub-task | B14: Component/page build — Design system token package (colors/type/spacing) | C14: FE: Design system token package (colors/type/spacing) | D14: DEV-FE-2 | E14: 8 | F14: sub
A15: Sub-task | B15: State wiring + form validation — Design system token package (colors/type/spacing) | C15: FE: Design system token package (colors/type/spacing) | D15: DEV-FE-2 | E15: 4 | F15: sub
A16: Sub-task | B16: E2E + a11y pass — Design system token package (colors/type/spacing) | C16: FE: Design system token package (colors/type/spacing) | D16: DEV-FE-2 | E16: 3 | F16: sub
... A579: Sub-task | B579: Review + finalize — Go-live retrospective (what went well / improve) | C579: PO: Go-live retrospective (what went well / improve) | D579: PO | E579: 2 | F579: sub

Sheet Workload
A1: Workload — Story Points per person per sprint (formula-driven from Stories sheet)
A2: Formulas use SUMIFS on Stories sheet. Target: ≤14 SP per dev per sprint; DES ≤7 (50% FTE).
A4: Assignee / Sprint | B4: S0 | C4: S1 | D4: S2 | E4: S3 | F4: S4 | G4: S5 | H4: S6 | I4: S7 | J4: S8 | K4: S9 | L4: S10 | M4: S11 | N4: S12 | O4: S13 | P4: S14 | Q4: S15 | R4: S16 | S4: S17 | T4: S18 | U4: S19 | V4: S20 | W4: S21 | X4: S22 | Y4: Total
A5: DEV-FE-1 | B5: =SUMIFS(Stories!J:J,Stories!E:E,"DEV-FE-1",Stories!G:G,"Sprint 0 — P0 close / Kick-off · Team onboarded, environments ready, CI/C") -> 3 | C5: =SUMIFS(Stories!J:J,Stories!E:E,"DEV-FE-1",Stories!G:G,"Sprint 1 — P1 Discover · Discovery M1 — employee records & org st") -> 3 | D5: =SUMIFS(Stories!J:J,Stories!E:E,"DEV-FE-1",Stories!G:G,"Sprint 2 — P1 Discover · Discovery M1 — positions & contracts + M") -> 0 | E5: =SUMIFS(Stories!J:J,Stories!E:E,"DEV-FE-1",Stories!G:G,"Sprint 3 — P1→P2 Design · Design system complete + all M1 wirefram") -> 5 | F5: =SUMIFS(Stories!J:J,Stories!E:E,"DEV-FE-1",Stories!G:G,"Sprint 4 — P2 Foundations · Tenancy model + SSO + RBAC scaffold") -> 8 | G5: =SUMIFS(Stories!J:J,Stories!E:E,"DEV-FE-1",Stories!G:G,"Sprint 5 — P2 Foundations · Audit log + platform shell + nav") -> 13 | H5: =SUMIFS(Stories!J:J,Stories!E:E,"DEV-FE-1",Stories!G:G,"Sprint 6 — P3 Core Build · Employee records CRUD + search + data mo") -> 13 | I5: =SUMIFS(Stories!J:J,Stories!E:E,"DEV-FE-1",Stories!G:G,"Sprint 7 — P3 Core Build · Org structure + positions + assignment") -> 13 | J5: =SUMIFS(Stories!J:J,Stories!E:E,"DEV-FE-1",Stories!G:G,"Sprint 8 — P3 Core Build · Contracts + documents vault + signed URL") -> 15 | K5: =SUMIFS(Stories!J:J,Stories!E:E,"DEV-FE-1",Stories!G:G,"Sprint 9 — P3 Core Build · Lifecycle events + approvals engine + no") -> 13 | L5: =SUMIFS(Stories!J:J,Stories!E:E,"DEV-FE-1",Stories!G:G,"Sprint 10 — P3→P4 · M1 polish + bulk import/export + M10 sca") -> 15 | M5: =SUMIFS(Stories!J:J,Stories!E:E,"DEV-FE-1",Stories!G:G,"Sprint 11 — P4 Adjacent · M10 users, roles, permissions admin") -> 13 | N5: =SUMIFS(Stories!J:J,Stories!E:E,"DEV-FE-1",Stories!G:G,"Sprint 12 — P4 Adjacent · M10 tenant config + org chart admin + ho") -> 13 | O5: =SUMIFS(Stories!J:J,Stories!E:E,"DEV-FE-1",Stories!G:G,"Sprint 13 — P4 Adjacent · M10 audit dashboard + integrations + web") -> 13 | P5: =SUMIFS(Stories!J:J,Stories!E:E,"DEV-FE-1",Stories!G:G,"Sprint 14 — P4→P5 · Feature-freeze — a11y + bundle + perf op") -> 10 | Q5: =SUMIFS(Stories!J:J,Stories!E:E,"DEV-FE-1",Stories!G:G,"Sprint 15 — P5 Harden · Load test + security scan fixes + DR dri") -> 5 | R5: =SUMIFS(Stories!J:J,Stories!E:E,"DEV-FE-1",Stories!G:G,"Sprint 16 — P5 Harden · Pen-test fixes + data migration dry-runs") -> 0 | S5: =SUMIFS(Stories!J:J,Stories!E:E,"DEV-FE-1",Stories!G:G,"Sprint 17 — P5→P6 · Holiday-reduced · UAT prep — scenarios, ") -> 3 | T5: =SUMIFS(Stories!J:J,Stories!E:E,"DEV-FE-1",Stories!G:G,"Sprint 18 — P6 UAT · UAT round 1 + defect burndown") -> 8 | U5: =SUMIFS(Stories!J:J,Stories!E:E,"DEV-FE-1",Stories!G:G,"Sprint 19 — P6 UAT · UAT round 2 + training content") -> 0 | V5: =SUMIFS(Stories!J:J,Stories!E:E,"DEV-FE-1",Stories!G:G,"Sprint 20 — P6 UAT · UAT round 3 + cutover rehearsal") -> 5 | W5: =SUMIFS(Stories!J:J,Stories!E:E,"DEV-FE-1",Stories!G:G,"Sprint 21 — P7 Cutover · Final fixes + go-live prep + rollback re") -> 5 | X5: =SUMIFS(Stories!J:J,Stories!E:E,"DEV-FE-1",Stories!G:G,"Sprint 22 — P7 Go-Live · GO-LIVE 14-Mar-2027 + Day-1 hypercare") -> 3 | Y5: =SUM(B5:X5) -> 179
A6: DEV-FE-2 | B6: =SUMIFS(Stories!J:J,Stories!E:E,"DEV-FE-2",Stories!G:G,"Sprint 0 — P0 close / Kick-off · Team onboarded, environments ready, CI/C") -> 3 | C6: =SUMIFS(Stories!J:J,Stories!E:E,"DEV-FE-2",Stories!G:G,"Sprint 1 — P1 Discover · Discovery M1 — employee records & org st") -> 0 | D6: =SUMIFS(Stories!J:J,Stories!E:E,"DEV-FE-2",Stories!G:G,"Sprint 2 — P1 Discover · Discovery M1 — positions & contracts + M") -> 0 | E6: =SUMIFS(Stories!J:J,Stories!E:E,"DEV-FE-2",Stories!G:G,"Sprint 3 — P1→P2 Design · Design system complete + all M1 wirefram") -> 5 | F6: =SUMIFS(Stories!J:J,Stories!E:E,"DEV-FE-2",Stories!G:G,"Sprint 4 — P2 Foundations · Tenancy model + SSO + RBAC scaffold") -> 3 | G6: =SUMIFS(Stories!J:J,Stories!E:E,"DEV-FE-2",Stories!G:G,"Sprint 5 — P2 Foundations · Audit log + platform shell + nav") -> 11 | H6: =SUMIFS(Stories!J:J,Stories!E:E,"DEV-FE-2",Stories!G:G,"Sprint 6 — P3 Core Build · Employee records CRUD + search + data mo") -> 16 | I6: =SUMIFS(Stories!J:J,Stories!E:E,"DEV-FE-2",Stories!G:G,"Sprint 7 — P3 Core Build · Org structure + positions + assignment") -> 15 | J6: =SUMIFS(Stories!J:J,Stories!E:E,"DEV-FE-2",Stories!G:G,"Sprint 8 — P3 Core Build · Contracts + documents vault + signed URL") -> 15 | K6: =SUMIFS(Stories!J:J,Stories!E:E,"DEV-FE-2",Stories!G:G,"Sprint 9 — P3 Core Build · Lifecycle events + approvals engine + no") -> 13 | L6: =SUMIFS(Stories!J:J,Stories!E:E,"DEV-FE-2",Stories!G:G,"Sprint 10 — P3→P4 · M1 polish + bulk import/export + M10 sca") -> 13 | M6: =SUMIFS(Stories!J:J,Stories!E:E,"DEV-FE-2",Stories!G:G,"Sprint 11 — P4 Adjacent · M10 users, roles, permissions admin") -> 5 | N6: =SUMIFS(Stories!J:J,Stories!E:E,"DEV-FE-2",Stories!G:G,"Sprint 12 — P4 Adjacent · M10 tenant config + org chart admin + ho") -> 13 | O6: =SUMIFS(Stories!J:J,Stories!E:E,"DEV-FE-2",Stories!G:G,"Sprint 13 — P4 Adjacent · M10 audit dashboard + integrations + web") -> 8 | P6: =SUMIFS(Stories!J:J,Stories!E:E,"DEV-FE-2",Stories!G:G,"Sprint 14 — P4→P5 · Feature-freeze — a11y + bundle + perf op") -> 10 | Q6: =SUMIFS(Stories!J:J,Stories!E:E,"DEV-FE-2",Stories!G:G,"Sprint 15 — P5 Harden · Load test + security scan fixes + DR dri") -> 3 | R6: =SUMIFS(Stories!J:J,Stories!E:E,"DEV-FE-2",Stories!G:G,"Sprint 16 — P5 Harden · Pen-test fixes + data migration dry-runs") -> 0 | S6: =SUMIFS(Stories!J:J,Stories!E:E,"DEV-FE-2",Stories!G:G,"Sprint 17 — P5→P6 · Holiday-reduced · UAT prep — scenarios, ") -> 0 | T6: =SUMIFS(Stories!J:J,Stories!E:E,"DEV-FE-2",Stories!G:G,"Sprint 18 — P6 UAT · UAT round 1 + defect burndown") -> 0 | U6: =SUMIFS(Stories!J:J,Stories!E:E,"DEV-FE-2",Stories!G:G,"Sprint 19 — P6 UAT · UAT round 2 + training content") -> 5 | V6: =SUMIFS(Stories!J:J,Stories!E:E,"DEV-FE-2",Stories!G:G,"Sprint 20 — P6 UAT · UAT round 3 + cutover rehearsal") -> 0 | W6: =SUMIFS(Stories!J:J,Stories!E:E,"DEV-FE-2",Stories!G:G,"Sprint 21 — P7 Cutover · Final fixes + go-live prep + rollback re") -> 0 | X6: =SUMIFS(Stories!J:J,Stories!E:E,"DEV-FE-2",Stories!G:G,"Sprint 22 — P7 Go-Live · GO-LIVE 14-Mar-2027 + Day-1 hypercare") -> 0 | Y6: =SUM(B6:X6) -> 138
A7: DEV-BE-1 | B7: =SUMIFS(Stories!J:J,Stories!E:E,"DEV-BE-1",Stories!G:G,"Sprint 0 — P0 close / Kick-off · Team onboarded, environments ready, CI/C") -> 7 | C7: =SUMIFS(Stories!J:J,Stories!E:E,"DEV-BE-1",Stories!G:G,"Sprint 1 — P1 Discover · Discovery M1 — employee records & org st") -> 5 | D7: =SUMIFS(Stories!J:J,Stories!E:E,"DEV-BE-1",Stories!G:G,"Sprint 2 — P1 Discover · Discovery M1 — positions & contracts + M") -> 3 | E7: =SUMIFS(Stories!J:J,Stories!E:E,"DEV-BE-1",Stories!G:G,"Sprint 3 — P1→P2 Design · Design system complete + all M1 wirefram") -> 3 | F7: =SUMIFS(Stories!J:J,Stories!E:E,"DEV-BE-1",Stories!G:G,"Sprint 4 — P2 Foundations · Tenancy model + SSO + RBAC scaffold") -> 18 | G7: =SUMIFS(Stories!J:J,Stories!E:E,"DEV-BE-1",Stories!G:G,"Sprint 5 — P2 Foundations · Audit log + platform shell + nav") -> 8 | H7: =SUMIFS(Stories!J:J,Stories!E:E,"DEV-BE-1",Stories!G:G,"Sprint 6 — P3 Core Build · Employee records CRUD + search + data mo") -> 13 | I7: =SUMIFS(Stories!J:J,Stories!E:E,"DEV-BE-1",Stories!G:G,"Sprint 7 — P3 Core Build · Org structure + positions + assignment") -> 15 | J7: =SUMIFS(Stories!J:J,Stories!E:E,"DEV-BE-1",Stories!G:G,"Sprint 8 — P3 Core Build · Contracts + documents vault + signed URL") -> 15 | K7: =SUMIFS(Stories!J:J,Stories!E:E,"DEV-BE-1",Stories!G:G,"Sprint 9 — P3 Core Build · Lifecycle events + approvals engine + no") -> 13 | L7: =SUMIFS(Stories!J:J,Stories!E:E,"DEV-BE-1",Stories!G:G,"Sprint 10 — P3→P4 · M1 polish + bulk import/export + M10 sca") -> 8 | M7: =SUMIFS(Stories!J:J,Stories!E:E,"DEV-BE-1",Stories!G:G,"Sprint 11 — P4 Adjacent · M10 users, roles, permissions admin") -> 15 | N7: =SUMIFS(Stories!J:J,Stories!E:E,"DEV-BE-1",Stories!G:G,"Sprint 12 — P4 Adjacent · M10 tenant config + org chart admin + ho") -> 10 | O7: =SUMIFS(Stories!J:J,Stories!E:E,"DEV-BE-1",Stories!G:G,"Sprint 13 — P4 Adjacent · M10 audit dashboard + integrations + web") -> 13 | P7: =SUMIFS(Stories!J:J,Stories!E:E,"DEV-BE-1",Stories!G:G,"Sprint 14 — P4→P5 · Feature-freeze — a11y + bundle + perf op") -> 8 | Q7: =SUMIFS(Stories!J:J,Stories!E:E,"DEV-BE-1",Stories!G:G,"Sprint 15 — P5 Harden · Load test + security scan fixes + DR dri") -> 18 | R7: =SUMIFS(Stories!J:J,Stories!E:E,"DEV-BE-1",Stories!G:G,"Sprint 16 — P5 Harden · Pen-test fixes + data migration dry-runs") -> 19 | S7: =SUMIFS(Stories!J:J,Stories!E:E,"DEV-BE-1",Stories!G:G,"Sprint 17 — P5→P6 · Holiday-reduced · UAT prep — scenarios, ") -> 5 | T7: =SUMIFS(Stories!J:J,Stories!E:E,"DEV-BE-1",Stories!G:G,"Sprint 18 — P6 UAT · UAT round 1 + defect burndown") -> 8 | U7: =SUMIFS(Stories!J:J,Stories!E:E,"DEV-BE-1",Stories!G:G,"Sprint 19 — P6 UAT · UAT round 2 + training content") -> 0 | V7: =SUMIFS(Stories!J:J,Stories!E:E,"DEV-BE-1",Stories!G:G,"Sprint 20 — P6 UAT · UAT round 3 + cutover rehearsal") -> 5 | W7: =SUMIFS(Stories!J:J,Stories!E:E,"DEV-BE-1",Stories!G:G,"Sprint 21 — P7 Cutover · Final fixes + go-live prep + rollback re") -> 5 | X7: =SUMIFS(Stories!J:J,Stories!E:E,"DEV-BE-1",Stories!G:G,"Sprint 22 — P7 Go-Live · GO-LIVE 14-Mar-2027 + Day-1 hypercare") -> 8 | Y7: =SUM(B7:X7) -> 222
A8: DEV-BE-2 | B8: =SUMIFS(Stories!J:J,Stories!E:E,"DEV-BE-2",Stories!G:G,"Sprint 0 — P0 close / Kick-off · Team onboarded, environments ready, CI/C") -> 5 | C8: =SUMIFS(Stories!J:J,Stories!E:E,"DEV-BE-2",Stories!G:G,"Sprint 1 — P1 Discover · Discovery M1 — employee records & org st") -> 5 | D8: =SUMIFS(Stories!J:J,Stories!E:E,"DEV-BE-2",Stories!G:G,"Sprint 2 — P1 Discover · Discovery M1 — positions & contracts + M") -> 3 | E8: =SUMIFS(Stories!J:J,Stories!E:E,"DEV-BE-2",Stories!G:G,"Sprint 3 — P1→P2 Design · Design system complete + all M1 wirefram") -> 3 | F8: =SUMIFS(Stories!J:J,Stories!E:E,"DEV-BE-2",Stories!G:G,"Sprint 4 — P2 Foundations · Tenancy model + SSO + RBAC scaffold") -> 18 | G8: =SUMIFS(Stories!J:J,Stories!E:E,"DEV-BE-2",Stories!G:G,"Sprint 5 — P2 Foundations · Audit log + platform shell + nav") -> 6 | H8: =SUMIFS(Stories!J:J,Stories!E:E,"DEV-BE-2",Stories!G:G,"Sprint 6 — P3 Core Build · Employee records CRUD + search + data mo") -> 16 | I8: =SUMIFS(Stories!J:J,Stories!E:E,"DEV-BE-2",Stories!G:G,"Sprint 7 — P3 Core Build · Org structure + positions + assignment") -> 13 | J8: =SUMIFS(Stories!J:J,Stories!E:E,"DEV-BE-2",Stories!G:G,"Sprint 8 — P3 Core Build · Contracts + documents vault + signed URL") -> 13 | K8: =SUMIFS(Stories!J:J,Stories!E:E,"DEV-BE-2",Stories!G:G,"Sprint 9 — P3 Core Build · Lifecycle events + approvals engine + no") -> 13 | L8: =SUMIFS(Stories!J:J,Stories!E:E,"DEV-BE-2",Stories!G:G,"Sprint 10 — P3→P4 · M1 polish + bulk import/export + M10 sca") -> 13 | M8: =SUMIFS(Stories!J:J,Stories!E:E,"DEV-BE-2",Stories!G:G,"Sprint 11 — P4 Adjacent · M10 users, roles, permissions admin") -> 3 | N8: =SUMIFS(Stories!J:J,Stories!E:E,"DEV-BE-2",Stories!G:G,"Sprint 12 — P4 Adjacent · M10 tenant config + org chart admin + ho") -> 6 | O8: =SUMIFS(Stories!J:J,Stories!E:E,"DEV-BE-2",Stories!G:G,"Sprint 13 — P4 Adjacent · M10 audit dashboard + integrations + web") -> 8 | P8: =SUMIFS(Stories!J:J,Stories!E:E,"DEV-BE-2",Stories!G:G,"Sprint 14 — P4→P5 · Feature-freeze — a11y + bundle + perf op") -> 11 | Q8: =SUMIFS(Stories!J:J,Stories!E:E,"DEV-BE-2",Stories!G:G,"Sprint 15 — P5 Harden · Load test + security scan fixes + DR dri") -> 15 | R8: =SUMIFS(Stories!J:J,Stories!E:E,"DEV-BE-2",Stories!G:G,"Sprint 16 — P5 Harden · Pen-test fixes + data migration dry-runs") -> 18 | S8: =SUMIFS(Stories!J:J,Stories!E:E,"DEV-BE-2",Stories!G:G,"Sprint 17 — P5→P6 · Holiday-reduced · UAT prep — scenarios, ") -> 3 | T8: =SUMIFS(Stories!J:J,Stories!E:E,"DEV-BE-2",Stories!G:G,"Sprint 18 — P6 UAT · UAT round 1 + defect burndown") -> 0 | U8: =SUMIFS(Stories!J:J,Stories!E:E,"DEV-BE-2",Stories!G:G,"Sprint 19 — P6 UAT · UAT round 2 + training content") -> 5 | V8: =SUMIFS(Stories!J:J,Stories!E:E,"DEV-BE-2",Stories!G:G,"Sprint 20 — P6 UAT · UAT round 3 + cutover rehearsal") -> 10 | W8: =SUMIFS(Stories!J:J,Stories!E:E,"DEV-BE-2",Stories!G:G,"Sprint 21 — P7 Cutover · Final fixes + go-live prep + rollback re") -> 8 | X8: =SUMIFS(Stories!J:J,Stories!E:E,"DEV-BE-2",Stories!G:G,"Sprint 22 — P7 Go-Live · GO-LIVE 14-Mar-2027 + Day-1 hypercare") -> 8 | Y8: =SUM(B8:X8) -> 203
A9: QA-1 | B9: =SUMIFS(Stories!J:J,Stories!E:E,"QA-1",Stories!G:G,"Sprint 0 — P0 close / Kick-off · Team onboarded, environments ready, CI/C") -> 2 | C9: =SUMIFS(Stories!J:J,Stories!E:E,"QA-1",Stories!G:G,"Sprint 1 — P1 Discover · Discovery M1 — employee records & org st") -> 3 | D9: =SUMIFS(Stories!J:J,Stories!E:E,"QA-1",Stories!G:G,"Sprint 2 — P1 Discover · Discovery M1 — positions & contracts + M") -> 0 | E9: =SUMIFS(Stories!J:J,Stories!E:E,"QA-1",Stories!G:G,"Sprint 3 — P1→P2 Design · Design system complete + all M1 wirefram") -> 8 | F9: =SUMIFS(Stories!J:J,Stories!E:E,"QA-1",Stories!G:G,"Sprint 4 — P2 Foundations · Tenancy model + SSO + RBAC scaffold") -> 5 | G9: =SUMIFS(Stories!J:J,Stories!E:E,"QA-1",Stories!G:G,"Sprint 5 — P2 Foundations · Audit log + platform shell + nav") -> 5 | H9: =SUMIFS(Stories!J:J,Stories!E:E,"QA-1",Stories!G:G,"Sprint 6 — P3 Core Build · Employee records CRUD + search + data mo") -> 8 | I9: =SUMIFS(Stories!J:J,Stories!E:E,"QA-1",Stories!G:G,"Sprint 7 — P3 Core Build · Org structure + positions + assignment") -> 5 | J9: =SUMIFS(Stories!J:J,Stories!E:E,"QA-1",Stories!G:G,"Sprint 8 — P3 Core Build · Contracts + documents vault + signed URL") -> 5 | K9: =SUMIFS(Stories!J:J,Stories!E:E,"QA-1",Stories!G:G,"Sprint 9 — P3 Core Build · Lifecycle events + approvals engine + no") -> 9 | L9: =SUMIFS(Stories!J:J,Stories!E:E,"QA-1",Stories!G:G,"Sprint 10 — P3→P4 · M1 polish + bulk import/export + M10 sca") -> 13 | M9: =SUMIFS(Stories!J:J,Stories!E:E,"QA-1",Stories!G:G,"Sprint 11 — P4 Adjacent · M10 users, roles, permissions admin") -> 9 | N9: =SUMIFS(Stories!J:J,Stories!E:E,"QA-1",Stories!G:G,"Sprint 12 — P4 Adjacent · M10 tenant config + org chart admin + ho") -> 3 | O9: =SUMIFS(Stories!J:J,Stories!E:E,"QA-1",Stories!G:G,"Sprint 13 — P4 Adjacent · M10 audit dashboard + integrations + web") -> 3 | P9: =SUMIFS(Stories!J:J,Stories!E:E,"QA-1",Stories!G:G,"Sprint 14 — P4→P5 · Feature-freeze — a11y + bundle + perf op") -> 8 | Q9: =SUMIFS(Stories!J:J,Stories!E:E,"QA-1",Stories!G:G,"Sprint 15 — P5 Harden · Load test + security scan fixes + DR dri") -> 3 | R9: =SUMIFS(Stories!J:J,Stories!E:E,"QA-1",Stories!G:G,"Sprint 16 — P5 Harden · Pen-test fixes + data migration dry-runs") -> 8 | S9: =SUMIFS(Stories!J:J,Stories!E:E,"QA-1",Stories!G:G,"Sprint 17 — P5→P6 · Holiday-reduced · UAT prep — scenarios, ") -> 8 | T9: =SUMIFS(Stories!J:J,Stories!E:E,"QA-1",Stories!G:G,"Sprint 18 — P6 UAT · UAT round 1 + defect burndown") -> 10 | U9: =SUMIFS(Stories!J:J,Stories!E:E,"QA-1",Stories!G:G,"Sprint 19 — P6 UAT · UAT round 2 + training content") -> 5 | V9: =SUMIFS(Stories!J:J,Stories!E:E,"QA-1",Stories!G:G,"Sprint 20 — P6 UAT · UAT round 3 + cutover rehearsal") -> 8 | W9: =SUMIFS(Stories!J:J,Stories!E:E,"QA-1",Stories!G:G,"Sprint 21 — P7 Cutover · Final fixes + go-live prep + rollback re") -> 2 | X9: =SUMIFS(Stories!J:J,Stories!E:E,"QA-1",Stories!G:G,"Sprint 22 — P7 Go-Live · GO-LIVE 14-Mar-2027 + Day-1 hypercare") -> 3 | Y9: =SUM(B9:X9) -> 133
A10: TL | B10: =SUMIFS(Stories!J:J,Stories!E:E,"TL",Stories!G:G,"Sprint 0 — P0 close / Kick-off · Team onboarded, environments ready, CI/C") -> 0 | C10: =SUMIFS(Stories!J:J,Stories!E:E,"TL",Stories!G:G,"Sprint 1 — P1 Discover · Discovery M1 — employee records & org st") -> 6 | D10: =SUMIFS(Stories!J:J,Stories!E:E,"TL",Stories!G:G,"Sprint 2 — P1 Discover · Discovery M1 — positions & contracts + M") -> 8 | E10: =SUMIFS(Stories!J:J,Stories!E:E,"TL",Stories!G:G,"Sprint 3 — P1→P2 Design · Design system complete + all M1 wirefram") -> 0 | F10: =SUMIFS(Stories!J:J,Stories!E:E,"TL",Stories!G:G,"Sprint 4 — P2 Foundations · Tenancy model + SSO + RBAC scaffold") -> 0 | G10: =SUMIFS(Stories!J:J,Stories!E:E,"TL",Stories!G:G,"Sprint 5 — P2 Foundations · Audit log + platform shell + nav") -> 0 | H10: =SUMIFS(Stories!J:J,Stories!E:E,"TL",Stories!G:G,"Sprint 6 — P3 Core Build · Employee records CRUD + search + data mo") -> 0 | I10: =SUMIFS(Stories!J:J,Stories!E:E,"TL",Stories!G:G,"Sprint 7 — P3 Core Build · Org structure + positions + assignment") -> 0 | J10: =SUMIFS(Stories!J:J,Stories!E:E,"TL",Stories!G:G,"Sprint 8 — P3 Core Build · Contracts + documents vault + signed URL") -> 0 | K10: =SUMIFS(Stories!J:J,Stories!E:E,"TL",Stories!G:G,"Sprint 9 — P3 Core Build · Lifecycle events + approvals engine + no") -> 0 | L10: =SUMIFS(Stories!J:J,Stories!E:E,"TL",Stories!G:G,"Sprint 10 — P3→P4 · M1 polish + bulk import/export + M10 sca") -> 0 | M10: =SUMIFS(Stories!J:J,Stories!E:E,"TL",Stories!G:G,"Sprint 11 — P4 Adjacent · M10 users, roles, permissions admin") -> 0 | N10: =SUMIFS(Stories!J:J,Stories!E:E,"TL",Stories!G:G,"Sprint 12 — P4 Adjacent · M10 tenant config + org chart admin + ho") -> 0 | O10: =SUMIFS(Stories!J:J,Stories!E:E,"TL",Stories!G:G,"Sprint 13 — P4 Adjacent · M10 audit dashboard + integrations + web") -> 0 | P10: =SUMIFS(Stories!J:J,Stories!E:E,"TL",Stories!G:G,"Sprint 14 — P4→P5 · Feature-freeze — a11y + bundle + perf op") -> 0 | Q10: =SUMIFS(Stories!J:J,Stories!E:E,"TL",Stories!G:G,"Sprint 15 — P5 Harden · Load test + security scan fixes + DR dri") -> 0 | R10: =SUMIFS(Stories!J:J,Stories!E:E,"TL",Stories!G:G,"Sprint 16 — P5 Harden · Pen-test fixes + data migration dry-runs") -> 0 | S10: =SUMIFS(Stories!J:J,Stories!E:E,"TL",Stories!G:G,"Sprint 17 — P5→P6 · Holiday-reduced · UAT prep — scenarios, ") -> 0 | T10: =SUMIFS(Stories!J:J,Stories!E:E,"TL",Stories!G:G,"Sprint 18 — P6 UAT · UAT round 1 + defect burndown") -> 0 | U10: =SUMIFS(Stories!J:J,Stories!E:E,"TL",Stories!G:G,"Sprint 19 — P6 UAT · UAT round 2 + training content") -> 0 | V10: =SUMIFS(Stories!J:J,Stories!E:E,"TL",Stories!G:G,"Sprint 20 — P6 UAT · UAT round 3 + cutover rehearsal") -> 0 | W10: =SUMIFS(Stories!J:J,Stories!E:E,"TL",Stories!G:G,"Sprint 21 — P7 Cutover · Final fixes + go-live prep + rollback re") -> 0 | X10: =SUMIFS(Stories!J:J,Stories!E:E,"TL",Stories!G:G,"Sprint 22 — P7 Go-Live · GO-LIVE 14-Mar-2027 + Day-1 hypercare") -> 0 | Y10: =SUM(B10:X10) -> 14
A11: DES-1 | B11: =SUMIFS(Stories!J:J,Stories!E:E,"DES-1",Stories!G:G,"Sprint 0 — P0 close / Kick-off · Team onboarded, environments ready, CI/C") -> 0 | C11: =SUMIFS(Stories!J:J,Stories!E:E,"DES-1",Stories!G:G,"Sprint 1 — P1 Discover · Discovery M1 — employee records & org st") -> 10 | D11: =SUMIFS(Stories!J:J,Stories!E:E,"DES-1",Stories!G:G,"Sprint 2 — P1 Discover · Discovery M1 — positions & contracts + M") -> 20 | E11: =SUMIFS(Stories!J:J,Stories!E:E,"DES-1",Stories!G:G,"Sprint 3 — P1→P2 Design · Design system complete + all M1 wirefram") -> 15 | F11: =SUMIFS(Stories!J:J,Stories!E:E,"DES-1",Stories!G:G,"Sprint 4 — P2 Foundations · Tenancy model + SSO + RBAC scaffold") -> 5 | G11: =SUMIFS(Stories!J:J,Stories!E:E,"DES-1",Stories!G:G,"Sprint 5 — P2 Foundations · Audit log + platform shell + nav") -> 0 | H11: =SUMIFS(Stories!J:J,Stories!E:E,"DES-1",Stories!G:G,"Sprint 6 — P3 Core Build · Employee records CRUD + search + data mo") -> 0 | I11: =SUMIFS(Stories!J:J,Stories!E:E,"DES-1",Stories!G:G,"Sprint 7 — P3 Core Build · Org structure + positions + assignment") -> 0 | J11: =SUMIFS(Stories!J:J,Stories!E:E,"DES-1",Stories!G:G,"Sprint 8 — P3 Core Build · Contracts + documents vault + signed URL") -> 0 | K11: =SUMIFS(Stories!J:J,Stories!E:E,"DES-1",Stories!G:G,"Sprint 9 — P3 Core Build · Lifecycle events + approvals engine + no") -> 0 | L11: =SUMIFS(Stories!J:J,Stories!E:E,"DES-1",Stories!G:G,"Sprint 10 — P3→P4 · M1 polish + bulk import/export + M10 sca") -> 3 | M11: =SUMIFS(Stories!J:J,Stories!E:E,"DES-1",Stories!G:G,"Sprint 11 — P4 Adjacent · M10 users, roles, permissions admin") -> 0 | N11: =SUMIFS(Stories!J:J,Stories!E:E,"DES-1",Stories!G:G,"Sprint 12 — P4 Adjacent · M10 tenant config + org chart admin + ho") -> 0 | O11: =SUMIFS(Stories!J:J,Stories!E:E,"DES-1",Stories!G:G,"Sprint 13 — P4 Adjacent · M10 audit dashboard + integrations + web") -> 0 | P11: =SUMIFS(Stories!J:J,Stories!E:E,"DES-1",Stories!G:G,"Sprint 14 — P4→P5 · Feature-freeze — a11y + bundle + perf op") -> 0 | Q11: =SUMIFS(Stories!J:J,Stories!E:E,"DES-1",Stories!G:G,"Sprint 15 — P5 Harden · Load test + security scan fixes + DR dri") -> 0 | R11: =SUMIFS(Stories!J:J,Stories!E:E,"DES-1",Stories!G:G,"Sprint 16 — P5 Harden · Pen-test fixes + data migration dry-runs") -> 0 | S11: =SUMIFS(Stories!J:J,Stories!E:E,"DES-1",Stories!G:G,"Sprint 17 — P5→P6 · Holiday-reduced · UAT prep — scenarios, ") -> 0 | T11: =SUMIFS(Stories!J:J,Stories!E:E,"DES-1",Stories!G:G,"Sprint 18 — P6 UAT · UAT round 1 + defect burndown") -> 1 | U11: =SUMIFS(Stories!J:J,Stories!E:E,"DES-1",Stories!G:G,"Sprint 19 — P6 UAT · UAT round 2 + training content") -> 3 | V11: =SUMIFS(Stories!J:J,Stories!E:E,"DES-1",Stories!G:G,"Sprint 20 — P6 UAT · UAT round 3 + cutover rehearsal") -> 0 | W11: =SUMIFS(Stories!J:J,Stories!E:E,"DES-1",Stories!G:G,"Sprint 21 — P7 Cutover · Final fixes + go-live prep + rollback re") -> 0 | X11: =SUMIFS(Stories!J:J,Stories!E:E,"DES-1",Stories!G:G,"Sprint 22 — P7 Go-Live · GO-LIVE 14-Mar-2027 + Day-1 hypercare") -> 0 | Y11: =SUM(B11:X11) -> 57
A12: PO | B12: =SUMIFS(Stories!J:J,Stories!E:E,"PO",Stories!G:G,"Sprint 0 — P0 close / Kick-off · Team onboarded, environments ready, CI/C") -> 0 | C12: =SUMIFS(Stories!J:J,Stories!E:E,"PO",Stories!G:G,"Sprint 1 — P1 Discover · Discovery M1 — employee records & org st") -> 6 | D12: =SUMIFS(Stories!J:J,Stories!E:E,"PO",Stories!G:G,"Sprint 2 — P1 Discover · Discovery M1 — positions & contracts + M") -> 9 | E12: =SUMIFS(Stories!J:J,Stories!E:E,"PO",Stories!G:G,"Sprint 3 — P1→P2 Design · Design system complete + all M1 wirefram") -> 2 | F12: =SUMIFS(Stories!J:J,Stories!E:E,"PO",Stories!G:G,"Sprint 4 — P2 Foundations · Tenancy model + SSO + RBAC scaffold") -> 0 | G12: =SUMIFS(Stories!J:J,Stories!E:E,"PO",Stories!G:G,"Sprint 5 — P2 Foundations · Audit log + platform shell + nav") -> 0 | H12: =SUMIFS(Stories!J:J,Stories!E:E,"PO",Stories!G:G,"Sprint 6 — P3 Core Build · Employee records CRUD + search + data mo") -> 0 | I12: =SUMIFS(Stories!J:J,Stories!E:E,"PO",Stories!G:G,"Sprint 7 — P3 Core Build · Org structure + positions + assignment") -> 0 | J12: =SUMIFS(Stories!J:J,Stories!E:E,"PO",Stories!G:G,"Sprint 8 — P3 Core Build · Contracts + documents vault + signed URL") -> 0 | K12: =SUMIFS(Stories!J:J,Stories!E:E,"PO",Stories!G:G,"Sprint 9 — P3 Core Build · Lifecycle events + approvals engine + no") -> 0 | L12: =SUMIFS(Stories!J:J,Stories!E:E,"PO",Stories!G:G,"Sprint 10 — P3→P4 · M1 polish + bulk import/export + M10 sca") -> 0 | M12: =SUMIFS(Stories!J:J,Stories!E:E,"PO",Stories!G:G,"Sprint 11 — P4 Adjacent · M10 users, roles, permissions admin") -> 0 | N12: =SUMIFS(Stories!J:J,Stories!E:E,"PO",Stories!G:G,"Sprint 12 — P4 Adjacent · M10 tenant config + org chart admin + ho") -> 0 | O12: =SUMIFS(Stories!J:J,Stories!E:E,"PO",Stories!G:G,"Sprint 13 — P4 Adjacent · M10 audit dashboard + integrations + web") -> 0 | P12: =SUMIFS(Stories!J:J,Stories!E:E,"PO",Stories!G:G,"Sprint 14 — P4→P5 · Feature-freeze — a11y + bundle + perf op") -> 0 | Q12: =SUMIFS(Stories!J:J,Stories!E:E,"PO",Stories!G:G,"Sprint 15 — P5 Harden · Load test + security scan fixes + DR dri") -> 0 | R12: =SUMIFS(Stories!J:J,Stories!E:E,"PO",Stories!G:G,"Sprint 16 — P5 Harden · Pen-test fixes + data migration dry-runs") -> 0 | S12: =SUMIFS(Stories!J:J,Stories!E:E,"PO",Stories!G:G,"Sprint 17 — P5→P6 · Holiday-reduced · UAT prep — scenarios, ") -> 11 | T12: =SUMIFS(Stories!J:J,Stories!E:E,"PO",Stories!G:G,"Sprint 18 — P6 UAT · UAT round 1 + defect burndown") -> 3 | U12: =SUMIFS(Stories!J:J,Stories!E:E,"PO",Stories!G:G,"Sprint 19 — P6 UAT · UAT round 2 + training content") -> 12 | V12: =SUMIFS(Stories!J:J,Stories!E:E,"PO",Stories!G:G,"Sprint 20 — P6 UAT · UAT round 3 + cutover rehearsal") -> 2 | W12: =SUMIFS(Stories!J:J,Stories!E:E,"PO",Stories!G:G,"Sprint 21 — P7 Cutover · Final fixes + go-live prep + rollback re") -> 5 | X12: =SUMIFS(Stories!J:J,Stories!E:E,"PO",Stories!G:G,"Sprint 22 — P7 Go-Live · GO-LIVE 14-Mar-2027 + Day-1 hypercare") -> 3 | Y12: =SUM(B12:X12) -> 53
A13: TEAM TOTAL | B13: =SUM(B5:B12) -> 20 | C13: =SUM(C5:C12) -> 38 | D13: =SUM(D5:D12) -> 43 | E13: =SUM(E5:E12) -> 41 | F13: =SUM(F5:F12) -> 57 | G13: =SUM(G5:G12) -> 43 | H13: =SUM(H5:H12) -> 66 | I13: =SUM(I5:I12) -> 61 | ... X13: =SUM(X5:X12) -> 25 | Y13: =SUM(B13:X13) -> 999

Sheet Bug-Log
A1: Bug log — Jira CSV-ready bug tracker (log defects here; bulk-import into PRX)
A2: Workflow: Open → Triaged → In Progress → In Review → Ready QA → Verified → Closed. SLA: P0 same-day · P1 within sprint · P2 next sprint · P3 quarterly · P4 backlog.
A4: Issue Type | B4: Summary | C4: Environment | D4: Steps to reproduce | E4: Expected | F4: Actual | G4: Severity | H4: Priority | I4: Component | J4: Labels | K4: Linked Story (Epic Link or Story key) | L4: Reporter
A5: Bug | J5: bug
A6: Bug | J6: bug
A7: Bug | J7: bug
A8: Bug | J8: bug
A9: Bug | J9: bug
A10: Bug | J10: bug
A11: Bug | J11: bug
A12: Bug | J12: bug
A13: Bug | J13: bug
A14: Bug | J14: bug
A15: Bug | J15: bug
A16: Bug | J16: bug
... A204: Bug | J204: bug

Sheet Capacity-Check
A1: Capacity check — sprint-by-sprint utilisation vs target
A2: Planned SP = sum from Stories sheet. Capacity SP = Sprints sheet target. Utilisation = planned ÷ capacity. Target ≤95%. Over 100% = over-allocated.
A4: Sprint | B4: Phase gate | C4: Goal | D4: Planned SP | E4: Capacity SP | F4: Utilisation %
A5: S0 | B5: P0 close / Kick-off | C5: Team onboarded, environments ready, CI/CD green, design system scaffold | D5: =SUMIFS(Stories!J:J,Stories!G:G,"Sprint 0 — P0 close / Kick-off · Team onboarded, environments ready, CI/C") -> 20 | E5: 20 | F5: =IFERROR(D5/E5,0) -> 1
A6: S1 | B6: P1 Discover | C6: Discovery M1 — employee records & org structure flow | D6: =SUMIFS(Stories!J:J,Stories!G:G,"Sprint 1 — P1 Discover · Discovery M1 — employee records & org st") -> 38 | E6: 35 | F6: =IFERROR(D6/E6,0) -> 1.0857143
A7: S2 | B7: P1 Discover | C7: Discovery M1 — positions & contracts + M10 discovery | D7: =SUMIFS(Stories!J:J,Stories!G:G,"Sprint 2 — P1 Discover · Discovery M1 — positions & contracts + M") -> 43 | E7: 45 | F7: =IFERROR(D7/E7,0) -> 0.95555556
A8: S3 | B8: P1→P2 Design | C8: Design system complete + all M1 wireframes signed off | D8: =SUMIFS(Stories!J:J,Stories!G:G,"Sprint 3 — P1→P2 Design · Design system complete + all M1 wirefram") -> 41 | E8: 50 | F8: =IFERROR(D8/E8,0) -> 0.82
A9: S4 | B9: P2 Foundations | C9: Tenancy model + SSO + RBAC scaffold | D9: =SUMIFS(Stories!J:J,Stories!G:G,"Sprint 4 — P2 Foundations · Tenancy model + SSO + RBAC scaffold") -> 57 | E9: 56 | F9: =IFERROR(D9/E9,0) -> 1.0178571
A10: S5 | B10: P2 Foundations | C10: Audit log + platform shell + nav | D10: =SUMIFS(Stories!J:J,Stories!G:G,"Sprint 5 — P2 Foundations · Audit log + platform shell + nav") -> 43 | E10: 56 | F10: =IFERROR(D10/E10,0) -> 0.76785714
A11: S6 | B11: P3 Core Build | C11: Employee records CRUD + search + data model in place | D11: =SUMIFS(Stories!J:J,Stories!G:G,"Sprint 6 — P3 Core Build · Employee records CRUD + search + data mo") -> 66 | E11: 56 | F11: =IFERROR(D11/E11,0) -> 1.1785714
A12: S7 | B12: P3 Core Build | C12: Org structure + positions + assignment | D12: =SUMIFS(Stories!J:J,Stories!G:G,"Sprint 7 — P3 Core Build · Org structure + positions + assignment") -> 61 | E12: 56 | F12: =IFERROR(D12/E12,0) -> 1.0892857
A13: S8 | B13: P3 Core Build | C13: Contracts + documents vault + signed URLs | D13: =SUMIFS(Stories!J:J,Stories!G:G,"Sprint 8 — P3 Core Build · Contracts + documents vault + signed URL") -> 63 | E13: 56 | F13: =IFERROR(D13/E13,0) -> 1.125
A14: S9 | B14: P3 Core Build | C14: Lifecycle events + approvals engine + notifications | D14: =SUMIFS(Stories!J:J,Stories!G:G,"Sprint 9 — P3 Core Build · Lifecycle events + approvals engine + no") -> 61 | E14: 56 | F14: =IFERROR(D14/E14,0) -> 1.0892857
A15: S10 | B15: P3→P4 | C15: M1 polish + bulk import/export + M10 scaffold | D15: =SUMIFS(Stories!J:J,Stories!G:G,"Sprint 10 — P3→P4 · M1 polish + bulk import/export + M10 sca") -> 65 | E15: 56 | F15: =IFERROR(D15/E15,0) -> 1.1607143
A16: S11 | B16: P4 Adjacent | C16: M10 users, roles, permissions admin | D16: =SUMIFS(Stories!J:J,Stories!G:G,"Sprint 11 — P4 Adjacent · M10 users, roles, permissions admin") -> 45 | E16: 56 | F16: =IFERROR(D16/E16,0) -> 0.80357143
A17: S12 | B17: P4 Adjacent | C17: M10 tenant config + org chart admin + holiday calendar | D17: =SUMIFS(Stories!J:J,Stories!G:G,"Sprint 12 — P4 Adjacent · M10 tenant config + org chart admin + ho") -> 45 | E17: 56 | F17: =IFERROR(D17/E17,0) -> 0.80357143
A18: S13 | B18: P4 Adjacent | C18: M10 audit dashboard + integrations + webhooks + API tokens | D18: =SUMIFS(Stories!J:J,Stories!G:G,"Sprint 13 — P4 Adjacent · M10 audit dashboard + integrations + web") -> 45 | E18: 56 | F18: =IFERROR(D18/E18,0) -> 0.80357143
A19: S14 | B19: P4→P5 | C19: Feature-freeze — a11y + bundle + perf optimizations | D19: =SUMIFS(Stories!J:J,Stories!G:G,"Sprint 14 — P4→P5 · Feature-freeze — a11y + bundle + perf op") -> 47 | E19: 56 | F19: =IFERROR(D19/E19,0) -> 0.83928571
A20: S15 | B20: P5 Harden | C20: Load test + security scan fixes + DR drill | D20: =SUMIFS(Stories!J:J,Stories!G:G,"Sprint 15 — P5 Harden · Load test + security scan fixes + DR dri") -> 44 | E20: 56 | F20: =IFERROR(D20/E20,0) -> 0.78571429
A21: S16 | B21: P5 Harden | C21: Pen-test fixes + data migration dry-runs | D21: =SUMIFS(Stories!J:J,Stories!G:G,"Sprint 16 — P5 Harden · Pen-test fixes + data migration dry-runs") -> 45 | E21: 56 | F21: =IFERROR(D21/E21,0) -> 0.80357143
A22: S17 | B22: P5→P6 | C22: Holiday-reduced · UAT prep — scenarios, test data, env | D22: =SUMIFS(Stories!J:J,Stories!G:G,"Sprint 17 — P5→P6 · Holiday-reduced · UAT prep — scenarios, ") -> 30 | E22: 35 | F22: =IFERROR(D22/E22,0) -> 0.85714286
A23: S18 | B23: P6 UAT | C23: UAT round 1 + defect burndown | D23: =SUMIFS(Stories!J:J,Stories!G:G,"Sprint 18 — P6 UAT · UAT round 1 + defect burndown") -> 30 | E23: 56 | F23: =IFERROR(D23/E23,0) -> 0.53571429
A24: S19 | B24: P6 UAT | C24: UAT round 2 + training content | D24: =SUMIFS(Stories!J:J,Stories!G:G,"Sprint 19 — P6 UAT · UAT round 2 + training content") -> 30 | E24: 56 | F24: =IFERROR(D24/E24,0) -> 0.53571429
A25: S20 | B25: P6 UAT | C25: UAT round 3 + cutover rehearsal | D25: =SUMIFS(Stories!J:J,Stories!G:G,"Sprint 20 — P6 UAT · UAT round 3 + cutover rehearsal") -> 30 | E25: 56 | F25: =IFERROR(D25/E25,0) -> 0.53571429
A26: S21 | B26: P7 Cutover | C26: Final fixes + go-live prep + rollback rehearsal | D26: =SUMIFS(Stories!J:J,Stories!G:G,"Sprint 21 — P7 Cutover · Final fixes + go-live prep + rollback re") -> 25 | E26: 56 | F26: =IFERROR(D26/E26,0) -> 0.44642857
A27: S22 | B27: P7 Go-Live | C27: GO-LIVE 14-Mar-2027 + Day-1 hypercare | D27: =SUMIFS(Stories!J:J,Stories!G:G,"Sprint 22 — P7 Go-Live · GO-LIVE 14-Mar-2027 + Day-1 hypercare") -> 25 | E27: 56 | F27: =IFERROR(D27/E27,0) -> 0.44642857
